Workbook

Sheet Option_Portfolio
B3: # contracts | C3: option | D3: underlying | E3: K | F3: T (in years) | G3: σ (annual) | H3: risk free rate | I3: contract size
B4: 7000 | C4: long put | D4: NESN | E4: 85 | F4: 0.5 | G4: 0.17 | H4: 0.01 | I4: 1000
B5: 2000 | C5: short call | D5: SREN | E5: 120 | F5: 0.5 | G5: 0.22 | H5: 0.01 | I5: 1000
F6: "=T-t"
G16: =D372 * Option_Portfolio!B4* Option_Portfolio!I4 * Underlying_Assets!C365 -> 0

Sheet Underlying_Assets
C2: Beta
B3: NSEN | C3: 0.75
B4: SREN | C4: 1.1
A7: date | C7: NESN | D7: SREN | F7: SMI | H7: R_NSEN | I7: R_SREN | K7: log returns | L7: log returns
A8: 45232 | C8: 100.52 | D8: 100.4 | F8: 0.0083865592
A9: 45233 | C9: 99.75 | D9: 99.26 | F9: -0.0011619935 | H9: =(C9-C8)/C8 -> -0.0076601671 | I9: =(D9-D8)/D8 -> -0.011354582 | K9: =LN(C9/C8) -> -0.0076896569 | L9: =LN(D9/D8) -> -0.011419537
A10: 45236 | C10: 99.87 | D10: 99.1 | F10: -0.00027577402 | H10: =(C10-C9)/C9 -> 0.0012030075 | I10: =(D10-D9)/D9 -> -0.0016119283 | K10: =LN(C10/C9) -> 0.0012022845 | L10: =LN(D10/D9) -> -0.0016132288
A11: 45237 | C11: 99.62 | D11: 98.84 | F11: -0.00054094184 | H11: =(C11-C10)/C10 -> -0.0025032542 | I11: =(D11-D10)/D10 -> -0.0026236125 | K11: =LN(C11/C10) -> -0.0025063926 | L11: =LN(D11/D10) -> -0.0026270602
A12: 45238 | C12: 99.07 | D12: 98.7 | F12: 0.0022730268 | H12: =(C12-C11)/C11 -> -0.0055209797 | I12: =(D12-D11)/D11 -> -0.0014164306 | K12: =LN(C12/C11) -> -0.0055362767 | L12: =LN(D12/D11) -> -0.0014174347
A13: 45239 | C13: 99.91 | D13: 98.36 | F13: 0.0047124541 | H13: =(C13-C12)/C12 -> 0.0084788533 | I13: =(D13-D12)/D12 -> -0.0034447822 | K13: =LN(C13/C12) -> 0.0084431098 | L13: =LN(D13/D12) -> -0.0034507291
A14: 45240 | C14: 99.38 | D14: 97.96 | F14: -0.0084204991 | H14: =(C14-C13)/C13 -> -0.0053047743 | I14: =(D14-D13)/D13 -> -0.0040666938 | K14: =LN(C14/C13) -> -0.0053188946 | L14: =LN(D14/D13) -> -0.0040749853
A15: 45243 | C15: 98.9 | D15: 99.2 | F15: 0.0033195704 | H15: =(C15-C14)/C14 -> -0.0048299457 | I15: =(D15-D14)/D14 -> 0.012658228 | K15: =LN(C15/C14) -> -0.0048416475 | L15: =LN(D15/D14) -> 0.012578782
A16: 45244 | C16: 99.4 | D16: 99.1 | F16: 0.011835031 | H16: =(C16-C15)/C15 -> 0.0050556117 | I16: =(D16-D15)/D15 -> -0.0010080645 | K16: =LN(C16/C15) -> 0.005042875 | L16: =LN(D16/D15) -> -0.001008573
A17: 45245 | C17: 99.6 | D17: 99.14 | F17: -0.00070323644 | H17: =(C17-C16)/C16 -> 0.0020120724 | I17: =(D17-D16)/D16 -> 0.00040363269 | K17: =LN(C17/C16) -> 0.0020100509 | L17: =LN(D17/D16) -> 0.00040355126
A18: 45246 | C18: 98.63 | D18: 99.06 | F18: -0.0060818873 | H18: =(C18-C17)/C17 -> -0.0097389558 | I18: =(D18-D17)/D17 -> -0.00080693968 | K18: =LN(C18/C17) -> -0.0097866896 | L18: =LN(D18/D17) -> -0.00080726543 | P18: =_xlfn.STDEV.S(Underlying_Assets!I114:I365) -> 0.017050205
A19: 45247 | C19: 98.99 | D19: 99.98 | F19: 0.0088601213 | H19: =(C19-C18)/C18 -> 0.0036500051 | I19: =(D19-D18)/D18 -> 0.0092873006 | K19: =LN(C19/C18) -> 0.00364336 | L19: =LN(D19/D18) -> 0.0092444388
A20: 45250 | C20: 98.29 | D20: 100.95 | F20: 0.00027018316 | H20: =(C20-C19)/C19 -> -0.0070714214 | I20: =(D20-D19)/D19 -> 0.0097019404 | K20: =LN(C20/C19) -> -0.0070965424 | L20: =LN(D20/D19) -> 0.0096551788
A21: 45251 | C21: 99.75 | D21: 101.55 | F21: 0.0039073032 | H21: =(C21-C20)/C20 -> 0.014854003 | I21: =(D21-D20)/D20 -> 0.0059435364 | K21: =LN(C21/C20) -> 0.014744763 | L21: =LN(D21/D20) -> 0.0059259433
A22: 45252 | C22: 100.3 | D22: 101.85 | F22: 0.0046518141 | H22: =(C22-C21)/C21 -> 0.0055137845 | I22: =(D22-D21)/D21 -> 0.0029542097 | K22: =LN(C22/C21) -> 0.0054986392 | L22: =LN(D22/D21) -> 0.0029498546
A23: 45254 | C23: 100.48 | D23: 102.65 | F23: 0.0043508575 | H23: =(C23-C22)/C22 -> 0.0017946162 | I23: =(D23-D22)/D22 -> 0.0078546883 | K23: =LN(C23/C22) -> 0.0017930078 | L23: =LN(D23/D22) -> 0.0078240008
A24: 45257 | C24: 100.22 | D24: 103.05 | F24: -0.0053738537 | H24: =(C24-C23)/C23 -> -0.0025875796 | I24: =(D24-D23)/D23 -> 0.0038967365 | K24: =LN(C24/C23) -> -0.0025909332 | L24: =LN(D24/D23) -> 0.0038891639
A25: 45258 | C25: 99.4 | D25: 103.3 | F25: -0.0056075 | H25: =(C25-C24)/C24 -> -0.0081819996 | I25: =(D25-D24)/D24 -> 0.0024260068 | K25: =LN(C25/C24) -> -0.0082156559 | L25: =LN(D25/D24) -> 0.0024230688 | R25: =D372 * Option_Portfolio!B4* Option_Portfolio!I4 * Underlying_Assets!C365 -> 0
A26: 45259 | C26: 99.13 | D26: 102.75 | F26: 0.0039495287 | H26: =(C26-C25)/C25 -> -0.0027162978 | I26: =(D26-D25)/D25 -> -0.0053242982 | K26: =LN(C26/C25) -> -0.0027199936 | L26: =LN(D26/D25) -> -0.0053385227
A27: 45260 | C27: 99.35 | D27: 103.25 | F27: 0.0047625058 | H27: =(C27-C26)/C26 -> 0.002219308 | I27: =(D27-D26)/D26 -> 0.00486618 | K27: =LN(C27/C26) -> 0.002216849 | L27: =LN(D27/D26) -> 0.0048543785
A28: 45261 | C28: 98.95 | D28: 98.34 | F28: 0.0030438512 | H28: =(C28-C27)/C27 -> -0.0040261701 | I28: =(D28-D27)/D27 -> -0.047554479 | K28: =LN(C28/C27) -> -0.0040342969 | L28: =LN(D28/D27) -> -0.04872237
A29: 45264 | C29: 99.97 | D29: 99.6 | F29: 0.0059771462 | H29: =(C29-C28)/C28 -> 0.010308236 | I29: =(D29-D28)/D28 -> 0.012812691 | K29: =LN(C29/C28) -> 0.010255469 | L29: =LN(D29/D28) -> 0.012731303
A30: 45265 | C30: 99.62 | D30: 99.06 | F30: 0.0011294192 | H30: =(C30-C29)/C29 -> -0.0035010503 | I30: =(D30-D29)/D29 -> -0.0054216867 | K30: =LN(C30/C29) -> -0.0035071933 | L30: =LN(D30/D29) -> -0.0054364374
A31: 45266 | C31: 99.4 | D31: 98.76 | F31: 0.0033573699 | H31: =(C31-C30)/C30 -> -0.0022083919 | I31: =(D31-D30)/D30 -> -0.0030284676 | K31: =LN(C31/C30) -> -0.002210834 | L31: =LN(D31/D30) -> -0.0030330627
A32: 45267 | C32: 98.67 | D32: 98.66 | F32: -0.0030469645 | H32: =(C32-C31)/C31 -> -0.0073440644 | I32: =(D32-D31)/D31 -> -0.0010125557 | K32: =LN(C32/C31) -> -0.0073711648 | L32: =LN(D32/D31) -> -0.0010130687
A33: 45268 | C33: 99.38 | D33: 98.88 | F33: 0.009451714 | H33: =(C33-C32)/C32 -> 0.0071957028 | I33: =(D33-D32)/D32 -> 0.0022298804 | K33: =LN(C33/C32) -> 0.0071699373 | L33: =LN(D33/D32) -> 0.0022273979
A34: 45271 | C34: 99.02 | D34: 99.1 | F34: 0.0052917619 | H34: =(C34-C33)/C33 -> -0.0036224592 | I34: =(D34-D33)/D33 -> 0.0022249191 | K34: =LN(C34/C33) -> -0.0036290362 | L34: =LN(D34/D33) -> 0.0022224476
A35: 45272 | C35: 98.94 | D35: 99.94 | F35: 0.0018743351 | H35: =(C35-C34)/C34 -> -0.00080791759 | I35: =(D35-D34)/D34 -> 0.0084762866 | K35: =LN(C35/C34) -> -0.00080824413 | L35: =LN(D35/D34) -> 0.0084405646
A36: 45273 | C36: 98.43 | D36: 100.45 | F36: 0.0033799044 | H36: =(C36-C35)/C35 -> -0.0051546392 | I36: =(D36-D35)/D35 -> 0.0051030618 | K36: =LN(C36/C35) -> -0.0051679702 | L36: =LN(D36/D35) -> 0.0050900853
A37: 45274 | C37: 97.72 | D37: 95.5 | F37: 0.0018806022 | H37: =(C37-C36)/C36 -> -0.007213248 | I37: =(D37-D36)/D36 -> -0.049278248 | K37: =LN(C37/C36) -> -0.0072393893 | L37: =LN(D37/D36) -> -0.050533844
... A80: 45343 | C80: 99.12 | D80: 101.9 | F80: -0.0024632162 | H80: =(C80-C79)/C79 -> -0.0048192771 | I80: =(D80-D79)/D79 -> -0.0082725061 | K80: =LN(C80/C79) -> -0.0048309273 | L80: =LN(D80/D79) -> -0.0083069131
A81: 45344 | C81: 94.24 | D81: 103.95 | F81: -0.0037251146 | H81: =(C81-C80)/C80 -> -0.049233253 | I81: =(D81-D80)/D80 -> 0.020117763 | K81: =LN(C81/C80) -> -0.050486517 | L81: =LN(D81/D80) -> 0.019918074 | Q81: =Underlying_Assets!C114*(1+Underlying_Assets!H114) -> 94.181387
A82: 45345 | C82: 95.35 | D82: 106.5 | F82: 0.0097125687 | H82: =(C82-C81)/C81 -> 0.011778438 | I82: =(D82-D81)/D81 -> 0.024531025 | K82: =LN(C82/C81) -> 0.011709612 | L82: =LN(D82/D81) -> 0.024234971
A83: 45348 | C83: 94.29 | D83: 105.85 | F83: -0.0038162945 | H83: =(C83-C82)/C82 -> -0.011116938 | I83: =(D83-D82)/D82 -> -0.0061032864 | K83: =LN(C83/C82) -> -0.011179193 | L83: =LN(D83/D82) -> -0.0061219876
A84: 45349 | C84: 93.68 | D84: 105 | F84: -0.0010850788 | H84: =(C84-C83)/C83 -> -0.0064694029 | I84: =(D84-D83)/D83 -> -0.0080302315 | K84: =LN(C84/C83) -> -0.0064904202 | L84: =LN(D84/D83) -> -0.0080626474
A85: 45350 | C85: 92.05 | D85: 105.8 | F85: -0.0022788665 | H85: =(C85-C84)/C84 -> -0.017399658 | I85: =(D85-D84)/D84 -> 0.0076190476 | K85: =LN(C85/C84) -> -0.017552812 | L85: =LN(D85/D84) -> 0.0075901693
...

Sheet Part 1
B3: solution at row 365
O5: Portfolio total | R5: VaR(00%, 1) sharp diagonal model formula: | S5: Alpha at 99% Normal | T5: Portfolio beta | U5: Variance SMI
O6: (sum here of portfolio positions) | R6: alpha * |portfolio beta| * variance SMI * W | S6: 2.33 | T6: sum(weight * beta i) | U6: =_xlfn.VAR.S(Underlying_Assets!F8:F365) -> 4.8388209e-05
A7: date | T7: weight = position value I / total portfolio value
A8: 45232
A9: 45233
A10: 45236
A11: 45237
A12: 45238
A13: 45239
A14: 45240
A15: 45243
A16: 45244
A17: 45245
A18: 45246
A19: 45247
... A365: 45772
C366: 1.1)
D367: Asset Normal approach with | E367: Delta Method | F367: t todat = 0
D369: NESN (long) | E369: SREN (short)
A371: 45772 | C371: d1 | D371: =(LN(Underlying_Assets!C365/Option_Portfolio!$E$4) + (Option_Portfolio!$H$4 + (Option_Portfolio!$G$4^2)/2) * (Option_Portfolio!$F$4)) / (Option_Portfolio!$G$4 * SQRT(Option_Portfolio!$F$4)) -> 0.17380855 | E371: =(LN(Underlying_Assets!D365/Option_Portfolio!$E$5) + (Option_Portfolio!$H$5 + (Option_Portfolio!$G$5^2)/2) * (Option_Portfolio!$F$5)) / (Option_Portfolio!$G$5 * SQRT(Option_Portfolio!$F$5)) -> 1.3175439 | H371: historical data (past 250)
C372: delta_put/call_t | D372: =_xlfn.NORM.S.DIST(D371, TRUE) - 1 -> -0.43100796 | E372: =_xlfn.NORM.S.DIST(E371, TRUE) -> 0.90617182 | H372: correlation: | I372: =CORREL(Underlying_Assets!H114:H365, Underlying_Assets!I114:I365) -> 0.28291699
C373: (Delta) Exposure | D373: =D372 * Option_Portfolio!B4* Option_Portfolio!I4 * Underlying_Assets!C365 -> -2.5868236e+08 | E373: =E372 * -Option_Portfolio!B5* Option_Portfolio!I4 * Underlying_Assets!D365 -> -2.6242736e+08 | H373: daily volatility right one
C374: alpha | D374: 2.33 | E374: 2.33 | H374: SREN | I374: NESN
H375: =_xlfn.STDEV.S(Underlying_Assets!I114:I365) -> 0.017050205 | I375: =_xlfn.STDEV.S(Underlying_Assets!H114:H365) -> 0.012067291
B376: individual | C376: VaR(99%,1) | D376: =D374 * ABS(D373) * I375 -> 7273317.2 | E376: =E374 * ABS(E373) * H375 -> 10425446
B377: individual | C377: ES(99%,1) | D377: =2.665 * D376 -> 19383390 | E377: =2.665 * E376 -> 27783813
D378: diversified | E378: individual sum | F378: benefit
B379: total | C379: VaR(99%,1) | D379: {=E374*SQRT(MMULT((D373:E373), MMULT(M380:N381, TRANSPOSE(D373:E373))))} -> 14300241 | E379: =D376+E376 -> 17698763 | F379: =E379-D379 -> 3398522.4 | L379: VCV | M379: NESN | N379: SREN
B380: total | C380: ES(99%,1) | D380: =2.665 * D381 -> 16356284 | E380: =D377+E377 -> 47167204 | F380: =E380-D380 -> 30810920 | L380: NESN | M380: =I375^2 -> 0.00014561952 | N380: =I372 * H375 * I375 -> 5.8210111e-05
C381: daily volatility | D381: {=SQRT(MMULT((D373:E373),MMULT(M380:N381,TRANSPOSE(D373:E373))))} -> 6137442.3 | L381: SREN | M381: =I372 * H375 * I375 -> 5.8210111e-05 | N381: =H375^2 -> 0.00029070949
C384: 1.2)
C385: SMI Exposure | D385: =Underlying_Assets!C3*'Part 1'!D373 -> -1.9401177e+08 | E385: =Underlying_Assets!C4*'Part 1'!E373 -> -2.8867009e+08
C386: total: | D386: =D385+E385 -> -4.8268186e+08
B388: total | C388: VaR(99%,1) | D388: =D374*ABS(D386)*_xlfn.STDEV.S(Underlying_Assets!F115:F365) -> 8414917
B389: total | C389: ES(99%,1) | D389: =ABS(2.665 * D390 * (D373+E373)) -> 10391047
C390: sigma p | D390: =_xlfn.STDEV.S(Underlying_Assets!F115:F365) -> 0.0074822624 | M390: {=SQRT(BR2^2+Q396:Q645^2+2*BT2*BR2*O390)} -> #VALUE!
D391: T | E391: 0.5 | M391: {=SQRT(BQ391^2+Q396:Q645^2+2*BS391*BQ391*Q396:Q645)} -> #VALUE!
C392: 1.3) | D392: T - 1day = | E392: =0.5-1/250 -> 0.496 | F392: Todays portfolio value = | G392: =L395 -> -28226585
P393: potential change in value
...

Sheet FI_Portfolio
B3: # bonds | C3: maturity in years | D3: annual coupon
A4: A | B4: 2000000 | C4: 1 | D4: zero
A5: B | B5: -1500000 | C5: 3 | D5: 5
A6: C | B6: 4000000 | C6: 5 | D6: 2
B9: Notes:
B10: Negative #bonds means you are short

Sheet TSIR
B1: 1y | C1: 2y | D1: 3y | E1: 4y | F1: 5y | G1: Price Bond 1 | H1: Price Bond 2 | I1: Price Bond 3 | J1: Portfolio | L1: Day Yield_1 | M1: Day Yield_2 | N1: Day Yield_3 | O1: Day Yield_4 | P1: Day Yield_5 | Q1: Last_250 days | R1: Simulated scenario 1 | S1: Simulated scenario 2 | T1: Simulated scenario 3 | U1: Simulated scenario 4 | V1: Simulated scenario 5 | X1: BOND 1 | Y1: BOND 2 | Z1: BOND 3 | AA1: Portfolio | AB1: Returns | AC1: Returns Sorted | AD1: 1st Percentile | AE1: VAR | AF1: Mean below VAR | AG1: ES | AH1: # bonds | AI1: maturity (years) | AJ1: coupon | AK1: rate (%) | AL1: Price | AM1: Total Value
A2: 44200 | B2: 0.1 | C2: 0.11 | D2: 0.16 | E2: 0.26005084 | F2: 0.36 | G2: =100/((1+B2/100)^1) -> 99.9001 | H2: =SUM(5/(1+B2/100)^1, 5/(1+C2/100)^2, 105/(1+D2/100)^3) -> 114.48163 | I2: =SUM(2/(1+B2/100)^1, 2/(1+C2/100)^2, 2/(1+D2/100)^3, 2/(1+E2/100)^4, 102/(1+F2/100)^5) -> 108.14703 | J2: =G2*2000000+H2*-1500000+I2*4000000 -> 4.6066589e+08 | K2: 2.2) | L2: dy1 | M2: dy2 | N2: dy2 | O2: dy4 | P2: dy5 | R2: 2.3) | AH2: 2000000 | AI2: 1 | AJ2: zero | AK2: 3.95 | AL2: =G1080 -> 96.200096 | AM2: =AH2*AL2 -> 1.9240019e+08
A3: 44201 | B3: 0.1 | C3: 0.13 | D3: 0.17 | E3: 0.27536133 | F3: 0.38 | G3: =100/((1+B3/100)^1) -> 99.9001 | H3: =SUM(5/(1+B3/100)^1, 5/(1+C3/100)^2, 105/(1+D3/100)^3) -> 114.44835 | I3: =SUM(2/(1+B3/100)^1, 2/(1+C3/100)^2, 2/(1+D3/100)^3, 2/(1+E3/100)^4, 102/(1+F3/100)^5) -> 108.04467 | J3: =G3*2000000+H3*-1500000+I3*4000000 -> 4.6030635e+08 | L3: =B3-B2 -> 0 | M3: =C3-C2 -> 0.02 | N3: =D3-D2 -> 0.01 | O3: =E3-E2 -> 0.015310492 | P3: =F3-F2 -> 0.02 | Q3: 1 | R3: =TSIR!$B$1080/100+TSIR!L830/100 -> 0.0398 | S3: =TSIR!$C$1080/100+TSIR!M830/100 -> 0.0377 | T3: =TSIR!$D$1080/100+TSIR!N830/100 -> 0.0378 | U3: =TSIR!$E$1080/100+TSIR!O830/100 -> 0.037644 | V3: =TSIR!$F$1080/100+TSIR!P830/100 -> 0.0389 | X3: =100/((1+R3)^1) -> 96.172341 | Y3: =SUM(5/(1+R3)^1, 5/(1+S3)^2, 105/(1+T3)^3) -> 103.39143 | Z3: =SUM(2/(1+R3)^1, 2/(1+S3)^2, 2/(1+T3)^3, 2/(1+U3)^4, 102/(1+V3)^5) -> 91.576619 | AA3: =X3*2000000+Y3*-1500000+Z3*4000000 -> 4.0356402e+08 | AB3: =(AA3-J$1080)/J$1080 -> -0.00033436361 | AC3: {=_xlfn._xlws.SORT(AB3:AB251)} -> -0.0064427647 | AD3: =_xlfn.PERCENTILE.INC(_xlfn.ANCHORARRAY(AC3),0.01) -> -0.0052332242 | AE3: =ABS(AD3*AM5) -> 2112647.4 | AF3: =AVERAGEIF(_xlfn.ANCHORARRAY(AC3),"<"&AD3) -> -0.0061727596 | AG3: =ABS(AM5*AF3) -> 2491936.9 | AH3: -1500000 | AI3: 3 | AJ3: 5 | AK3: 3.76 | AL3: =H1080 -> 103.44983 | AM3: =AL3*AH3 -> -1.5517475e+08
A4: 44202 | B4: 0.11 | C4: 0.14 | D4: 0.2 | E4: 0.31523797 | F4: 0.43 | G4: =100/((1+B4/100)^1) -> 99.890121 | H4: =SUM(5/(1+B4/100)^1, 5/(1+C4/100)^2, 105/(1+D4/100)^3) -> 114.35305 | I4: =SUM(2/(1+B4/100)^1, 2/(1+C4/100)^2, 2/(1+D4/100)^3, 2/(1+E4/100)^4, 102/(1+F4/100)^5) -> 107.79025 | J4: =G4*2000000+H4*-1500000+I4*4000000 -> 4.5941167e+08 | L4: =B4-B3 -> 0.01 | M4: =C4-C3 -> 0.01 | N4: =D4-D3 -> 0.03 | O4: =E4-E3 -> 0.039876643 | P4: =F4-F3 -> 0.05 | Q4: 2 | R4: =TSIR!$B$1080/100+TSIR!L831/100 -> 0.0399 | S4: =TSIR!$C$1080/100+TSIR!M831/100 -> 0.0381 | T4: =TSIR!$D$1080/100+TSIR!N831/100 -> 0.0383 | U4: =TSIR!$E$1080/100+TSIR!O831/100 -> 0.038397 | V4: =TSIR!$F$1080/100+TSIR!P831/100 -> 0.0394 | X4: =100/((1+R4)^1) -> 96.163093 | Y4: =SUM(5/(1+R4)^1, 5/(1+S4)^2, 105/(1+T4)^3) -> 103.25174 | Z4: =SUM(2/(1+R4)^1, 2/(1+S4)^2, 2/(1+T4)^3, 2/(1+U4)^4, 102/(1+V4)^5) -> 91.364899 | AA4: =X4*2000000+Y4*-1500000+Z4*4000000 -> 4.0290817e+08 | AB4: =(AA4-J$1080)/J$1080 -> -0.0019589563 | AC4: -0.0063084013 | AE4: 2.3) | AG4: 2.3) | AH4: 4000000 | AI4: 5 | AJ4: 2 | AK4: 3.88 | AL4: =I1080 -> 91.618389 | AM4: =AL4*AH4 -> 3.6647356e+08
A5: 44203 | B5: 0.11 | C5: 0.14 | D5: 0.22 | E5: 0.34002364 | F5: 0.46 | G5: =100/((1+B5/100)^1) -> 99.890121 | H5: =SUM(5/(1+B5/100)^1, 5/(1+C5/100)^2, 105/(1+D5/100)^3) -> 114.29057 | I5: =SUM(2/(1+B5/100)^1, 2/(1+C5/100)^2, 2/(1+D5/100)^3, 2/(1+E5/100)^4, 102/(1+F5/100)^5) -> 107.63813 | J5: =G5*2000000+H5*-1500000+I5*4000000 -> 4.588969e+08 | L5: =B5-B4 -> 0 | M5: =C5-C4 -> 0 | N5: =D5-D4 -> 0.02 | O5: =E5-E4 -> 0.024785673 | P5: =F5-F4 -> 0.03 | Q5: 3 | R5: =TSIR!$B$1080/100+TSIR!L832/100 -> 0.0395 | S5: =TSIR!$C$1080/100+TSIR!M832/100 -> 0.0374 | T5: =TSIR!$D$1080/100+TSIR!N832/100 -> 0.0375 | U5: =TSIR!$E$1080/100+TSIR!O832/100 -> 0.037833 | V5: =TSIR!$F$1080/100+TSIR!P832/100 -> 0.0386 | X5: =100/((1+R5)^1) -> 96.200096 | Y5: =SUM(5/(1+R5)^1, 5/(1+S5)^2, 105/(1+T5)^3) -> 103.47701 | Z5: =SUM(2/(1+R5)^1, 2/(1+S5)^2, 2/(1+T5)^3, 2/(1+U5)^4, 102/(1+V5)^5) -> 91.700339 | AA5: =X5*2000000+Y5*-1500000+Z5*4000000 -> 4.0398603e+08 | AB5: =(AA5-J$1080)/J$1080 -> 0.00071099103 | AC5: -0.0057671127 | AH5: Overall portfolio | AM5: =SUM(AM2:AM4) -> 4.03699e+08
A6: 44204 | B6: 0.1 | C6: 0.14 | D6: 0.24 | E6: 0.36533805 | F6: 0.49 | G6: =100/((1+B6/100)^1) -> 99.9001 | H6: =SUM(5/(1+B6/100)^1, 5/(1+C6/100)^2, 105/(1+D6/100)^3) -> 114.22865 | I6: =SUM(2/(1+B6/100)^1, 2/(1+C6/100)^2, 2/(1+D6/100)^3, 2/(1+E6/100)^4, 102/(1+F6/100)^5) -> 107.48644 | J6: =G6*2000000+H6*-1500000+I6*4000000 -> 4.5840299e+08 | L6: =B6-B5 -> -0.01 | M6: =C6-C5 -> 0 | N6: =D6-D5 -> 0.02 | O6: =E6-E5 -> 0.025314409 | P6: =F6-F5 -> 0.03 | Q6: 4 | R6: =TSIR!$B$1080/100+TSIR!L833/100 -> 0.0394 | S6: =TSIR!$C$1080/100+TSIR!M833/100 -> 0.0375 | T6: =TSIR!$D$1080/100+TSIR!N833/100 -> 0.0372 | U6: =TSIR!$E$1080/100+TSIR!O833/100 -> 0.037573 | V6: =TSIR!$F$1080/100+TSIR!P833/100 -> 0.0385 | X6: =100/((1+R6)^1) -> 96.209352 | Y6: =SUM(5/(1+R6)^1, 5/(1+S6)^2, 105/(1+T6)^3) -> 103.55819 | Z6: =SUM(2/(1+R6)^1, 2/(1+S6)^2, 2/(1+T6)^3, 2/(1+U6)^4, 102/(1+V6)^5) -> 91.744093 | AA6: =X6*2000000+Y6*-1500000+Z6*4000000 -> 4.040578e+08 | AB6: =(AA6-J$1080)/J$1080 -> 0.00088876623 | AC6: -0.004654845
A7: 44207 | B7: 0.1 | C7: 0.14 | D7: 0.22 | E7: 0.36043964 | F7: 0.5 | G7: =100/((1+B7/100)^1) -> 99.9001 | H7: =SUM(5/(1+B7/100)^1, 5/(1+C7/100)^2, 105/(1+D7/100)^3) -> 114.29107 | I7: =SUM(2/(1+B7/100)^1, 2/(1+C7/100)^2, 2/(1+D7/100)^3, 2/(1+E7/100)^4, 102/(1+F7/100)^5) -> 107.4385 | J7: =G7*2000000+H7*-1500000+I7*4000000 -> 4.581176e+08 | L7: =B7-B6 -> 0 | M7: =C7-C6 -> 0 | N7: =D7-D6 -> -0.02 | O7: =E7-E6 -> -0.0048984104 | P7: =F7-F6 -> 0.01 | Q7: 5 | R7: =TSIR!$B$1080/100+TSIR!L834/100 -> 0.04 | S7: =TSIR!$C$1080/100+TSIR!M834/100 -> 0.0381 | T7: =TSIR!$D$1080/100+TSIR!N834/100 -> 0.0383 | U7: =TSIR!$E$1080/100+TSIR!O834/100 -> 0.038329 | V7: =TSIR!$F$1080/100+TSIR!P834/100 -> 0.0395 | X7: =100/((1+R7)^1) -> 96.153846 | Y7: =SUM(5/(1+R7)^1, 5/(1+S7)^2, 105/(1+T7)^3) -> 103.25128 | Z7: =SUM(2/(1+R7)^1, 2/(1+S7)^2, 2/(1+T7)^3, 2/(1+U7)^4, 102/(1+V7)^5) -> 91.324731 | AA7: =X7*2000000+Y7*-1500000+Z7*4000000 -> 4.027297e+08 | AB7: =(AA7-J$1080)/J$1080 -> -0.002401051 | AC7: -0.004537979
A8: 44208 | B8: 0.11 | C8: 0.14 | D8: 0.23 | E8: 0.36541897 | F8: 0.5 | G8: =100/((1+B8/100)^1) -> 99.890121 | H8: =SUM(5/(1+B8/100)^1, 5/(1+C8/100)^2, 105/(1+D8/100)^3) -> 114.25936 | I8: =SUM(2/(1+B8/100)^1, 2/(1+C8/100)^2, 2/(1+D8/100)^3, 2/(1+E8/100)^4, 102/(1+F8/100)^5) -> 107.43732 | J8: =G8*2000000+H8*-1500000+I8*4000000 -> 4.5814048e+08 | L8: =B8-B7 -> 0.01 | M8: =C8-C7 -> 0 | N8: =D8-D7 -> 0.01 | O8: =E8-E7 -> 0.0049793222 | P8: =F8-F7 -> 0 | Q8: 6 | R8: =TSIR!$B$1080/100+TSIR!L835/100 -> 0.0391 | S8: =TSIR!$C$1080/100+TSIR!M835/100 -> 0.0366 | T8: =TSIR!$D$1080/100+TSIR!N835/100 -> 0.0368 | U8: =TSIR!$E$1080/100+TSIR!O835/100 -> 0.037383 | V8: =TSIR!$F$1080/100+TSIR!P835/100 -> 0.038 | X8: =100/((1+R8)^1) -> 96.237128 | Y8: =SUM(5/(1+R8)^1, 5/(1+S8)^2, 105/(1+T8)^3) -> 103.6766 | Z8: =SUM(2/(1+R8)^1, 2/(1+S8)^2, 2/(1+T8)^3, 2/(1+U8)^4, 102/(1+V8)^5) -> 91.954794 | AA8: =X8*2000000+Y8*-1500000+Z8*4000000 -> 4.0477853e+08 | AB8: =(AA8-J$1080)/J$1080 -> 0.0026740852 | AC8: -0.004254209
A9: 44209 | B9: 0.12 | C9: 0.14 | D9: 0.22 | E9: 0.35011298 | F9: 0.48 | G9: =100/((1+B9/100)^1) -> 99.880144 | H9: =SUM(5/(1+B9/100)^1, 5/(1+C9/100)^2, 105/(1+D9/100)^3) -> 114.29007 | I9: =SUM(2/(1+B9/100)^1, 2/(1+C9/100)^2, 2/(1+D9/100)^3, 2/(1+E9/100)^4, 102/(1+F9/100)^5) -> 107.53797 | J9: =G9*2000000+H9*-1500000+I9*4000000 -> 4.5847704e+08 | L9: =B9-B8 -> 0.01 | M9: =C9-C8 -> 0 | N9: =D9-D8 -> -0.01 | O9: =E9-E8 -> -0.01530599 | P9: =F9-F8 -> -0.02 | Q9: 7 | R9: =TSIR!$B$1080/100+TSIR!L836/100 -> 0.039 | S9: =TSIR!$C$1080/100+TSIR!M836/100 -> 0.0365 | T9: =TSIR!$D$1080/100+TSIR!N836/100 -> 0.0368 | U9: =TSIR!$E$1080/100+TSIR!O836/100 -> 0.037272 | V9: =TSIR!$F$1080/100+TSIR!P836/100 -> 0.0381 | X9: =100/((1+R9)^1) -> 96.246391 | Y9: =SUM(5/(1+R9)^1, 5/(1+S9)^2, 105/(1+T9)^3) -> 103.67796 | Z9: =SUM(2/(1+R9)^1, 2/(1+S9)^2, 2/(1+T9)^3, 2/(1+U9)^4, 102/(1+V9)^5) -> 91.915315 | AA9: =X9*2000000+Y9*-1500000+Z9*4000000 -> 4.046371e+08 | AB9: =(AA9-J$1080)/J$1080 -> 0.0023237461 | AC9: -0.0040958045
A10: 44210 | B10: 0.1 | C10: 0.16 | D10: 0.23 | E10: 0.36044743 | F10: 0.49 | G10: =100/((1+B10/100)^1) -> 99.9001 | H10: =SUM(5/(1+B10/100)^1, 5/(1+C10/100)^2, 105/(1+D10/100)^3) -> 114.25786 | I10: =SUM(2/(1+B10/100)^1, 2/(1+C10/100)^2, 2/(1+D10/100)^3, 2/(1+E10/100)^4, 102/(1+F10/100)^5) -> 107.48662 | J10: =G10*2000000+H10*-1500000+I10*4000000 -> 4.5835989e+08 | L10: =B10-B9 -> -0.02 | M10: =C10-C9 -> 0.02 | N10: =D10-D9 -> 0.01 | O10: =E10-E9 -> 0.010334455 | P10: =F10-F9 -> 0.01 | Q10: 8 | R10: =TSIR!$B$1080/100+TSIR!L837/100 -> 0.0391 | S10: =TSIR!$C$1080/100+TSIR!M837/100 -> 0.0368 | T10: =TSIR!$D$1080/100+TSIR!N837/100 -> 0.0368 | U10: =TSIR!$E$1080/100+TSIR!O837/100 -> 0.037063 | V10: =TSIR!$F$1080/100+TSIR!P837/100 -> 0.0379 | X10: =100/((1+R10)^1) -> 96.237128 | Y10: =SUM(5/(1+R10)^1, 5/(1+S10)^2, 105/(1+T10)^3) -> 103.67481 | Z10: =SUM(2/(1+R10)^1, 2/(1+S10)^2, 2/(1+T10)^3, 2/(1+U10)^4, 102/(1+V10)^5) -> 91.996994 | AA10: =X10*2000000+Y10*-1500000+Z10*4000000 -> 4.0495002e+08 | AB10: =(AA10-J$1080)/J$1080 -> 0.003098893 | AC10: -0.0039976163
A11: 44211 | B11: 0.1 | C11: 0.13 | D11: 0.2 | E11: 0.33023905 | F11: 0.46 | G11: =100/((1+B11/100)^1) -> 99.9001 | H11: =SUM(5/(1+B11/100)^1, 5/(1+C11/100)^2, 105/(1+D11/100)^3) -> 114.35454 | I11: =SUM(2/(1+B11/100)^1, 2/(1+C11/100)^2, 2/(1+D11/100)^3, 2/(1+E11/100)^4, 102/(1+F11/100)^5) -> 107.64069 | J11: =G11*2000000+H11*-1500000+I11*4000000 -> 4.5883114e+08 | L11: =B11-B10 -> 0 | M11: =C11-C10 -> -0.03 | N11: =D11-D10 -> -0.03 | O11: =E11-E10 -> -0.030208377 | P11: =F11-F10 -> -0.03 | Q11: 9 | R11: =TSIR!$B$1080/100+TSIR!L838/100 -> 0.0395 | S11: =TSIR!$C$1080/100+TSIR!M838/100 -> 0.0375 | T11: =TSIR!$D$1080/100+TSIR!N838/100 -> 0.0377 | U11: =TSIR!$E$1080/100+TSIR!O838/100 -> 0.037679 | V11: =TSIR!$F$1080/100+TSIR!P838/100 -> 0.0388 | X11: =100/((1+R11)^1) -> 96.200096 | Y11: =SUM(5/(1+R11)^1, 5/(1+S11)^2, 105/(1+T11)^3) -> 103.42176 | Z11: =SUM(2/(1+R11)^1, 2/(1+S11)^2, 2/(1+T11)^3, 2/(1+U11)^4, 102/(1+V11)^5) -> 91.618749 | AA11: =X11*2000000+Y11*-1500000+Z11*4000000 -> 4.0374254e+08 | AB11: =(AA11-J$1080)/J$1080 -> 0.00010785695 | AC11: -0.0039343892
A12: 44215 | B12: 0.1 | C12: 0.14 | D12: 0.21 | E12: 0.33025798 | F12: 0.45 | G12: =100/((1+B12/100)^1) -> 99.9001 | H12: =SUM(5/(1+B12/100)^1, 5/(1+C12/100)^2, 105/(1+D12/100)^3) -> 114.3223 | I12: =SUM(2/(1+B12/100)^1, 2/(1+C12/100)^2, 2/(1+D12/100)^3, 2/(1+E12/100)^4, 102/(1+F12/100)^5) -> 107.68932 | J12: =G12*2000000+H12*-1500000+I12*4000000 -> 4.5907404e+08 | L12: =B12-B11 -> 0 | M12: =C12-C11 -> 0.01 | N12: =D12-D11 -> 0.01 | O12: =E12-E11 -> 1.8926313e-05 | P12: =F12-F11 -> -0.01 | Q12: 10 | R12: =TSIR!$B$1080/100+TSIR!L839/100 -> 0.0396 | S12: =TSIR!$C$1080/100+TSIR!M839/100 -> 0.0374 | T12: =TSIR!$D$1080/100+TSIR!N839/100 -> 0.0372 | U12: =TSIR!$E$1080/100+TSIR!O839/100 -> 0.037718 | V12: =TSIR!$F$1080/100+TSIR!P839/100 -> 0.0388 | X12: =100/((1+R12)^1) -> 96.190843 | Y12: =SUM(5/(1+R12)^1, 5/(1+S12)^2, 105/(1+T12)^3) -> 103.55816 | Z12: =SUM(2/(1+R12)^1, 2/(1+S12)^2, 2/(1+T12)^3, 2/(1+U12)^4, 102/(1+V12)^5) -> 91.621253 | AA12: =X12*2000000+Y12*-1500000+Z12*4000000 -> 4.0352946e+08 | AB12: =(AA12-J$1080)/J$1080 -> -0.00041996831 | AC12: -0.0038349848
A13: 44216 | B13: 0.1 | C13: 0.13 | D13: 0.19 | E13: 0.32026831 | F13: 0.45 | G13: =100/((1+B13/100)^1) -> 99.9001 | H13: =SUM(5/(1+B13/100)^1, 5/(1+C13/100)^2, 105/(1+D13/100)^3) -> 114.3858 | I13: =SUM(2/(1+B13/100)^1, 2/(1+C13/100)^2, 2/(1+D13/100)^3, 2/(1+E13/100)^4, 102/(1+F13/100)^5) -> 107.6917 | J13: =G13*2000000+H13*-1500000+I13*4000000 -> 4.5898829e+08 | L13: =B13-B12 -> 0 | M13: =C13-C12 -> -0.01 | N13: =D13-D12 -> -0.02 | O13: =E13-E12 -> -0.0099896685 | P13: =F13-F12 -> 0 | Q13: 11 | R13: =TSIR!$B$1080/100+TSIR!L840/100 -> 0.0395 | S13: =TSIR!$C$1080/100+TSIR!M840/100 -> 0.0376 | T13: =TSIR!$D$1080/100+TSIR!N840/100 -> 0.0379 | U13: =TSIR!$E$1080/100+TSIR!O840/100 -> 0.038011 | V13: =TSIR!$F$1080/100+TSIR!P840/100 -> 0.039 | X13: =100/((1+R13)^1) -> 96.200096 | Y13: =SUM(5/(1+R13)^1, 5/(1+S13)^2, 105/(1+T13)^3) -> 103.36656 | Z13: =SUM(2/(1+R13)^1, 2/(1+S13)^2, 2/(1+T13)^3, 2/(1+U13)^4, 102/(1+V13)^5) -> 91.534025 | AA13: =X13*2000000+Y13*-1500000+Z13*4000000 -> 4.0348646e+08 | AB13: =(AA13-J$1080)/J$1080 -> -0.00052649386 | AC13: -0.0037940024
A14: 44217 | B14: 0.1 | C14: 0.13 | D14: 0.19 | E14: 0.32042425 | F14: 0.45 | G14: =100/((1+B14/100)^1) -> 99.9001 | H14: =SUM(5/(1+B14/100)^1, 5/(1+C14/100)^2, 105/(1+D14/100)^3) -> 114.3858 | I14: =SUM(2/(1+B14/100)^1, 2/(1+C14/100)^2, 2/(1+D14/100)^3, 2/(1+E14/100)^4, 102/(1+F14/100)^5) -> 107.69169 | J14: =G14*2000000+H14*-1500000+I14*4000000 -> 4.5898825e+08 | L14: =B14-B13 -> 0 | M14: =C14-C13 -> 0 | N14: =D14-D13 -> 0 | O14: =E14-E13 -> 0.00015593777 | P14: =F14-F13 -> 0 | Q14: 12 | R14: =TSIR!$B$1080/100+TSIR!L841/100 -> 0.0394 | S14: =TSIR!$C$1080/100+TSIR!M841/100 -> 0.037 | T14: =TSIR!$D$1080/100+TSIR!N841/100 -> 0.0373 | U14: =TSIR!$E$1080/100+TSIR!O841/100 -> 0.037642 | V14: =TSIR!$F$1080/100+TSIR!P841/100 -> 0.0385 | X14: =100/((1+R14)^1) -> 96.209352 | Y14: =SUM(5/(1+R14)^1, 5/(1+S14)^2, 105/(1+T14)^3) -> 103.53545 | Z14: =SUM(2/(1+R14)^1, 2/(1+S14)^2, 2/(1+T14)^3, 2/(1+U14)^4, 102/(1+V14)^5) -> 91.744908 | AA14: =X14*2000000+Y14*-1500000+Z14*4000000 -> 4.0409516e+08 | AB14: =(AA14-J$1080)/J$1080 -> 0.00098130639 | AC14: -0.0035473843
A15: 44218 | B15: 0.1 | C15: 0.13 | D15: 0.19 | E15: 0.31548957 | F15: 0.44 | G15: =100/((1+B15/100)^1) -> 99.9001 | H15: =SUM(5/(1+B15/100)^1, 5/(1+C15/100)^2, 105/(1+D15/100)^3) -> 114.3858 | I15: =SUM(2/(1+B15/100)^1, 2/(1+C15/100)^2, 2/(1+D15/100)^3, 2/(1+E15/100)^4, 102/(1+F15/100)^5) -> 107.74173 | J15: =G15*2000000+H15*-1500000+I15*4000000 -> 4.5918844e+08 | L15: =B15-B14 -> 0 | M15: =C15-C14 -> 0 | N15: =D15-D14 -> 0 | O15: =E15-E14 -> -0.0049346745 | P15: =F15-F14 -> -0.01 | Q15: 13 | R15: =TSIR!$B$1080/100+TSIR!L842/100 -> 0.04 | S15: =TSIR!$C$1080/100+TSIR!M842/100 -> 0.0381 | T15: =TSIR!$D$1080/100+TSIR!N842/100 -> 0.0381 | U15: =TSIR!$E$1080/100+TSIR!O842/100 -> 0.038187 | V15: =TSIR!$F$1080/100+TSIR!P842/100 -> 0.0393 | X15: =100/((1+R15)^1) -> 96.153846 | Y15: =SUM(5/(1+R15)^1, 5/(1+S15)^2, 105/(1+T15)^3) -> 103.3055 | Z15: =SUM(2/(1+R15)^1, 2/(1+S15)^2, 2/(1+T15)^3, 2/(1+U15)^4, 102/(1+V15)^5) -> 91.407597 | AA15: =X15*2000000+Y15*-1500000+Z15*4000000 -> 4.0297982e+08 | AB15: =(AA15-J$1080)/J$1080 -> -0.0017814706 | AC15: -0.0034760313
A16: 44221 | B16: 0.1 | C16: 0.13 | D16: 0.17 | E16: 0.29528304 | F16: 0.42 | G16: =100/((1+B16/100)^1) -> 99.9001 | H16: =SUM(5/(1+B16/100)^1, 5/(1+C16/100)^2, 105/(1+D16/100)^3) -> 114.44835 | I16: =SUM(2/(1+B16/100)^1, 2/(1+C16/100)^2, 2/(1+D16/100)^3, 2/(1+E16/100)^4, 102/(1+F16/100)^5) -> 107.84392 | J16: =G16*2000000+H16*-1500000+I16*4000000 -> 4.5950338e+08 | L16: =B16-B15 -> 0 | M16: =C16-C15 -> 0 | N16: =D16-D15 -> -0.02 | O16: =E16-E15 -> -0.020206532 | P16: =F16-F15 -> -0.02 | Q16: 14 | R16: =TSIR!$B$1080/100+TSIR!L843/100 -> 0.0394 | S16: =TSIR!$C$1080/100+TSIR!M843/100 -> 0.0372 | T16: =TSIR!$D$1080/100+TSIR!N843/100 -> 0.0377 | U16: =TSIR!$E$1080/100+TSIR!O843/100 -> 0.037834 | V16: =TSIR!$F$1080/100+TSIR!P843/100 -> 0.0386 | X16: =100/((1+R16)^1) -> 96.209352 | Y16: =SUM(5/(1+R16)^1, 5/(1+S16)^2, 105/(1+T16)^3) -> 103.42491 | Z16: =SUM(2/(1+R16)^1, 2/(1+S16)^2, 2/(1+T16)^3, 2/(1+U16)^4, 102/(1+V16)^5) -> 91.700199 | AA16: =X16*2000000+Y16*-1500000+Z16*4000000 -> 4.0408213e+08 | AB16: =(AA16-J$1080)/J$1080 -> 0.00094903325 | AC16: -0.0034286488
A17: 44222 | B17: 0.09 | C17: 0.11 | D17: 0.18 | E17: 0.300079 | F17: 0.42 | G17: =100/((1+B17/100)^1) -> 99.910081 | H17: =SUM(5/(1+B17/100)^1, 5/(1+C17/100)^2, 105/(1+D17/100)^3) -> 114.41956 | I17: =SUM(2/(1+B17/100)^1, 2/(1+C17/100)^2, 2/(1+D17/100)^3, 2/(1+E17/100)^4, 102/(1+F17/100)^5) -> 107.84395 | J17: =G17*2000000+H17*-1500000+I17*4000000 -> 4.5956661e+08 | L17: =B17-B16 -> -0.01 | M17: =C17-C16 -> -0.02 | N17: =D17-D16 -> 0.01 | O17: =E17-E16 -> 0.0047959577 | P17: =F17-F16 -> 0 | Q17: 15 | R17: =TSIR!$B$1080/100+TSIR!L844/100 -> 0.0395 | S17: =TSIR!$C$1080/100+TSIR!M844/100 -> 0.037 | T17: =TSIR!$D$1080/100+TSIR!N844/100 -> 0.0372 | U17: =TSIR!$E$1080/100+TSIR!O844/100 -> 0.037565 | V17: =TSIR!$F$1080/100+TSIR!P844/100 -> 0.0384 | X17: =100/((1+R17)^1) -> 96.200096 | Y17: =SUM(5/(1+R17)^1, 5/(1+S17)^2, 105/(1+T17)^3) -> 103.5622 | Z17: =SUM(2/(1+R17)^1, 2/(1+S17)^2, 2/(1+T17)^3, 2/(1+U17)^4, 102/(1+V17)^5) -> 91.786422 | AA17: =X17*2000000+Y17*-1500000+Z17*4000000 -> 4.0420257e+08 | AB17: =(AA17-J$1080)/J$1080 -> 0.0012473933 | AC17: -0.0031173841
... A251: 44560 | B251: 0.38 | C251: 0.73 | D251: 0.98 | E251: 1.1251701 | F251: 1.27 | G251: =100/((1+B251/100)^1) -> 99.621439 | H251: =SUM(5/(1+B251/100)^1, 5/(1+C251/100)^2, 105/(1+D251/100)^3) -> 111.88139 | I251: =SUM(2/(1+B251/100)^1, 2/(1+C251/100)^2, 2/(1+D251/100)^3, 2/(1+E251/100)^4, 102/(1+F251/100)^5) -> 103.58098 | J251: =G251*2000000+H251*-1500000+I251*4000000 -> 4.4574472e+08 | L251: =B251-B250 -> 0 | M251: =C251-C250 -> -0.02 | N251: =D251-D250 -> -0.01 | O251: =E251-E250 -> -0.015262368 | P251: =F251-F250 -> -0.02 | Q251: 249 | R251: =TSIR!$B$1080/100+TSIR!L1078/100 -> 0.0398 | S251: =TSIR!$C$1080/100+TSIR!M1078/100 -> 0.0379 | T251: =TSIR!$D$1080/100+TSIR!N1078/100 -> 0.0381 | U251: =TSIR!$E$1080/100+TSIR!O1078/100 -> 0.038109 | V251: =TSIR!$F$1080/100+TSIR!P1078/100 -> 0.039 | X251: =100/((1+R251)^1) -> 96.172341 | Y251: =SUM(5/(1+R251)^1, 5/(1+S251)^2, 105/(1+T251)^3) -> 103.30822 | Z251: =SUM(2/(1+R251)^1, 2/(1+S251)^2, 2/(1+T251)^3, 2/(1+U251)^4, 102/(1+V251)^5) -> 91.530712 | AA251: =X251*2000000+Y251*-1500000+Z251*4000000 -> 4.0350521e+08 | AB251: =(AA251-J$1080)/J$1080 -> -0.00048005105 | AC251: 0.0078965688
A252: 44561 | B252: 0.39 | C252: 0.73 | D252: 0.97 | E252: 1.1151673 | F252: 1.26 | G252: =100/((1+B252/100)^1) -> 99.611515 | H252: =SUM(5/(1+B252/100)^1, 5/(1+C252/100)^2, 105/(1+D252/100)^3) -> 111.9112 | I252: =SUM(2/(1+B252/100)^1, 2/(1+C252/100)^2, 2/(1+D252/100)^3, 2/(1+E252/100)^4, 102/(1+F252/100)^5) -> 103.62941 | J252: =G252*2000000+H252*-1500000+I252*4000000 -> 4.4587389e+08 | L252: =B252-B251 -> 0.01 | M252: =C252-C251 -> 0 | N252: =D252-D251 -> -0.01 | O252: =E252-E251 -> -0.010002831 | P252: =F252-F251 -> -0.01 | Q252: 250 | R252: =TSIR!$B$1080/100+TSIR!L1079/100 -> 0.0391 | S252: =TSIR!$C$1080/100+TSIR!M1079/100 -> 0.037 | T252: =TSIR!$D$1080/100+TSIR!N1079/100 -> 0.0369 | U252: =TSIR!$E$1080/100+TSIR!O1079/100 -> 0.037303 | V252: =TSIR!$F$1080/100+TSIR!P1079/100 -> 0.0379 | X252: =100/((1+R252)^1) -> 96.237128 | Y252: =SUM(5/(1+R252)^1, 5/(1+S252)^2, 105/(1+T252)^3) -> 103.64576 | Z252: =SUM(2/(1+R252)^1, 2/(1+S252)^2, 2/(1+T252)^3, 2/(1+U252)^4, 102/(1+V252)^5) -> 91.994158 | AA252: =X252*2000000+Y252*-1500000+Z252*4000000 -> 4.0498225e+08 | AB252: =(AA252-J$1080)/J$1080 -> 0.0031787248
A253: 44564 | B253: 0.4 | C253: 0.78 | D253: 1.04 | E253: 1.2050616 | F253: 1.37 | G253: =100/((1+B253/100)^1) -> 99.601594 | H253: =SUM(5/(1+B253/100)^1, 5/(1+C253/100)^2, 105/(1+D253/100)^3) -> 111.69396 | I253: =SUM(2/(1+B253/100)^1, 2/(1+C253/100)^2, 2/(1+D253/100)^3, 2/(1+E253/100)^4, 102/(1+F253/100)^5) -> 103.09773 | J253: =G253*2000000+H253*-1500000+I253*4000000 -> 4.4405317e+08 | L253: =B253-B252 -> 0.01 | M253: =C253-C252 -> 0.05 | N253: =D253-D252 -> 0.07 | O253: =E253-E252 -> 0.089894301 | P253: =F253-F252 -> 0.11
A254: 44565 | B254: 0.38 | C254: 0.77 | D254: 1.02 | E254: 1.1950194 | F254: 1.37 | G254: =100/((1+B254/100)^1) -> 99.621439 | H254: =SUM(5/(1+B254/100)^1, 5/(1+C254/100)^2, 105/(1+D254/100)^3) -> 111.7564 | I254: =SUM(2/(1+B254/100)^1, 2/(1+C254/100)^2, 2/(1+D254/100)^3, 2/(1+E254/100)^4, 102/(1+F254/100)^5) -> 103.10043 | J254: =G254*2000000+H254*-1500000+I254*4000000 -> 4.4400999e+08 | L254: =B254-B253 -> -0.02 | M254: =C254-C253 -> -0.01 | N254: =D254-D253 -> -0.02 | O254: =E254-E253 -> -0.010042218 | P254: =F254-F253 -> 0
A255: 44566 | B255: 0.41 | C255: 0.83 | D255: 1.1 | E255: 1.2650392 | F255: 1.43 | G255: =100/((1+B255/100)^1) -> 99.591674 | H255: =SUM(5/(1+B255/100)^1, 5/(1+C255/100)^2, 105/(1+D255/100)^3) -> 111.50746 | I255: =SUM(2/(1+B255/100)^1, 2/(1+C255/100)^2, 2/(1+D255/100)^3, 2/(1+E255/100)^4, 102/(1+F255/100)^5) -> 102.80611 | J255: =G255*2000000+H255*-1500000+I255*4000000 -> 4.4314659e+08 | L255: =B255-B254 -> 0.03 | M255: =C255-C254 -> 0.06 | N255: =D255-D254 -> 0.08 | O255: =E255-E254 -> 0.070019787 | P255: =F255-F254 -> 0.06
A256: 44567 | B256: 0.45 | C256: 0.88 | D256: 1.15 | E256: 1.3104957 | F256: 1.47 | G256: =100/((1+B256/100)^1) -> 99.552016 | H256: =SUM(5/(1+B256/100)^1, 5/(1+C256/100)^2, 105/(1+D256/100)^3) -> 111.35 | I256: =SUM(2/(1+B256/100)^1, 2/(1+C256/100)^2, 2/(1+D256/100)^3, 2/(1+E256/100)^4, 102/(1+F256/100)^5) -> 102.60997 | J256: =G256*2000000+H256*-1500000+I256*4000000 -> 4.425189e+08 | L256: =B256-B255 -> 0.04 | M256: =C256-C255 -> 0.05 | N256: =D256-D255 -> 0.05 | O256: =E256-E255 -> 0.045456536 | P256: =F256-F255 -> 0.04
A257: 44568 | B257: 0.43 | C257: 0.87 | D257: 1.17 | E257: 1.3350261 | F257: 1.5 | G257: =100/((1+B257/100)^1) -> 99.571841 | H257: =SUM(5/(1+B257/100)^1, 5/(1+C257/100)^2, 105/(1+D257/100)^3) -> 111.2918 | I257: =SUM(2/(1+B257/100)^1, 2/(1+C257/100)^2, 2/(1+D257/100)^3, 2/(1+E257/100)^4, 102/(1+F257/100)^5) -> 102.46772 | J257: =G257*2000000+H257*-1500000+I257*4000000 -> 4.4207686e+08 | L257: =B257-B256 -> -0.02 | M257: =C257-C256 -> -0.01 | N257: =D257-D256 -> 0.02 | O257: =E257-E256 -> 0.024530354 | P257: =F257-F256 -> 0.03
A258: 44571 | B258: 0.46 | C258: 0.92 | D258: 1.21 | E258: 1.3702671 | F258: 1.53 | G258: =100/((1+B258/100)^1) -> 99.542106 | H258: =SUM(5/(1+B258/100)^1, 5/(1+C258/100)^2, 105/(1+D258/100)^3) -> 111.16527 | I258: =SUM(2/(1+B258/100)^1, 2/(1+C258/100)^2, 2/(1+D258/100)^3, 2/(1+E258/100)^4, 102/(1+F258/100)^5) -> 102.32045 | J258: =G258*2000000+H258*-1500000+I258*4000000 -> 4.4161811e+08 | L258: =B258-B257 -> 0.03 | M258: =C258-C257 -> 0.05 | N258: =D258-D257 -> 0.04 | O258: =E258-E257 -> 0.035241011 | P258: =F258-F257 -> 0.03
A259: 44572 | B259: 0.46 | C259: 0.9 | D259: 1.22 | E259: 1.3652537 | F259: 1.51 | G259: =100/((1+B259/100)^1) -> 99.542106 | H259: =SUM(5/(1+B259/100)^1, 5/(1+C259/100)^2, 105/(1+D259/100)^3) -> 111.1372 | I259: =SUM(2/(1+B259/100)^1, 2/(1+C259/100)^2, 2/(1+D259/100)^3, 2/(1+E259/100)^4, 102/(1+F259/100)^5) -> 102.41421 | J259: =G259*2000000+H259*-1500000+I259*4000000 -> 4.4203523e+08 | L259: =B259-B258 -> 0 | M259: =C259-C258 -> -0.02 | N259: =D259-D258 -> 0.01 | O259: =E259-E258 -> -0.0050133658 | P259: =F259-F258 -> -0.02
A260: 44573 | B260: 0.48 | C260: 0.92 | D260: 1.21 | E260: 1.3552797 | F260: 1.5 | G260: =100/((1+B260/100)^1) -> 99.522293 | H260: =SUM(5/(1+B260/100)^1, 5/(1+C260/100)^2, 105/(1+D260/100)^3) -> 111.16428 | I260: =SUM(2/(1+B260/100)^1, 2/(1+C260/100)^2, 2/(1+D260/100)^3, 2/(1+E260/100)^4, 102/(1+F260/100)^5) -> 102.46098 | J260: =G260*2000000+H260*-1500000+I260*4000000 -> 4.4214207e+08 | L260: =B260-B259 -> 0.02 | M260: =C260-C259 -> 0.02 | N260: =D260-D259 -> -0.01 | O260: =E260-E259 -> -0.0099739805 | P260: =F260-F259 -> -0.01
A261: 44574 | B261: 0.47 | C261: 0.91 | D261: 1.18 | E261: 1.3252019 | F261: 1.47 | G261: =100/((1+B261/100)^1) -> 99.532199 | H261: =SUM(5/(1+B261/100)^1, 5/(1+C261/100)^2, 105/(1+D261/100)^3) -> 111.25586 | I261: =SUM(2/(1+B261/100)^1, 2/(1+C261/100)^2, 2/(1+D261/100)^3, 2/(1+E261/100)^4, 102/(1+F261/100)^5) -> 102.60558 | J261: =G261*2000000+H261*-1500000+I261*4000000 -> 4.4260293e+08 | L261: =B261-B260 -> -0.01 | M261: =C261-C260 -> -0.01 | N261: =D261-D260 -> -0.03 | O261: =E261-E260 -> -0.030077875 | P261: =F261-F260 -> -0.03
A262: 44575 | B262: 0.51 | C262: 0.99 | D262: 1.26 | E262: 1.4050158 | F262: 1.55 | G262: =100/((1+B262/100)^1) -> 99.492588 | H262: =SUM(5/(1+B262/100)^1, 5/(1+C262/100)^2, 105/(1+D262/100)^3) -> 111.00604 | I262: =SUM(2/(1+B262/100)^1, 2/(1+C262/100)^2, 2/(1+D262/100)^3, 2/(1+E262/100)^4, 102/(1+F262/100)^5) -> 102.21823 | J262: =G262*2000000+H262*-1500000+I262*4000000 -> 4.4134902e+08 | L262: =B262-B261 -> 0.04 | M262: =C262-C261 -> 0.08 | N262: =D262-D261 -> 0.08 | O262: =E262-E261 -> 0.079813967 | P262: =F262-F261 -> 0.08
A263: 44579 | B263: 0.58 | C263: 1.06 | D263: 1.35 | E263: 1.5003376 | F263: 1.65 | G263: =100/((1+B263/100)^1) -> 99.423345 | H263: =SUM(5/(1+B263/100)^1, 5/(1+C263/100)^2, 105/(1+D263/100)^3) -> 110.72661 | I263: =SUM(2/(1+B263/100)^1, 2/(1+C263/100)^2, 2/(1+D263/100)^3, 2/(1+E263/100)^4, 102/(1+F263/100)^5) -> 101.73823 | J263: =G263*2000000+H263*-1500000+I263*4000000 -> 4.397097e+08 | L263: =B263-B262 -> 0.07 | M263: =C263-C262 -> 0.07 | N263: =D263-D262 -> 0.09 | O263: =E263-E262 -> 0.095321732 | P263: =F263-F262 -> 0.1
A264: 44580 | B264: 0.57 | C264: 1.04 | D264: 1.33 | E264: 1.4753019 | F264: 1.62 | G264: =100/((1+B264/100)^1) -> 99.433231 | H264: =SUM(5/(1+B264/100)^1, 5/(1+C264/100)^2, 105/(1+D264/100)^3) -> 110.78878 | I264: =SUM(2/(1+B264/100)^1, 2/(1+C264/100)^2, 2/(1+D264/100)^3, 2/(1+E264/100)^4, 102/(1+F264/100)^5) -> 101.88102 | J264: =G264*2000000+H264*-1500000+I264*4000000 -> 4.4020736e+08 | L264: =B264-B263 -> -0.01 | M264: =C264-C263 -> -0.02 | N264: =D264-D263 -> -0.02 | O264: =E264-E263 -> -0.025035673 | P264: =F264-F263 -> -0.03
... A1080: 45772 | B1080: 3.95 | C1080: 3.74 | D1080: 3.76 | E1080: 3.7865 | F1080: 3.88 | G1080: =100/((1+B1080/100)^1) -> 96.200096 | H1080: =SUM(5/(1+B1080/100)^1, 5/(1+C1080/100)^2, 105/(1+D1080/100)^3) -> 103.44983 | I1080: =SUM(2/(1+B1080/100)^1, 2/(1+C1080/100)^2, 2/(1+D1080/100)^3, 2/(1+E1080/100)^4, 102/(1+F1080/100)^5) -> 91.618389 | J1080: =G1080*2000000+H1080*-1500000+I1080*4000000 -> 4.03699e+08 | L1080: =B1080-B1079 -> -0.02 | M1080: =C1080-C1079 -> -0.03 | N1080: =D1080-D1079 -> -0.04 | O1080: =E1080-E1079 -> -0.0418 | P1080: =F1080-F1079 -> -0.03
J1081: Portfolio Total
J1083: mean | M1083: Column 1 | N1083: Column 2 | O1083: Column 3 | P1083: Column 4 | Q1083: Column 5
J1084: =AVERAGE(J830:J1080) -> 4.0040764e+08 | L1084: Column 1 | M1084: 0.0020450727 | N1084: 0.0024368656 | O1084: 0.0023585266 | P1084: 0.0018014988 | Q1084: 0.0021975386
L1085: Column 2 | M1085: 0.0024368656 | N1085: 0.0035250994 | O1085: 0.0033856673 | P1085: 0.0025839473 | Q1085: 0.0032840304
L1086: Column 3 | M1086: 0.0023585266 | N1086: 0.0033856673 | O1086: 0.0036160992 | P1086: 0.0027346307 | Q1086: 0.0034779346
L1087: Column 4 | M1087: 0.0018014988 | N1087: 0.0025839473 | O1087: 0.0027346307 | P1087: 0.002383614 | Q1087: 0.0028606066
L1088: Column 5 | M1088: 0.0021975386 | N1088: 0.0032840304 | O1088: 0.0034779346 | P1088: 0.0028606066 | Q1088: 0.0037056214
M1092: 0.03 | N1092: 0.03 | O1092: 0.02 | P1092: -0.0221 | Q1092: 0.01
...

Sheet Part2
D5: # bonds | E5: maturity in years | F5: annual coupon | G5: Assume face value
C6: 1 | D6: 2000000 | E6: 1 | F6: zero | G6: 100
C7: 2 | D7: -1500000 | E7: 3 | F7: 5
C8: 3 | D8: 4000000 | E8: 5 | F8: 2
B11: Q1 | D11: 1 | E11: 2 | F11: 3
B12: 2.1) | C12: Individual bond price 25.april.25 | D12: =TSIR!G1080 -> 96.200096 | E12: =TSIR!H1080 -> 103.44983 | F12: =TSIR!I1080 -> 91.618389 | S12: =(T18*$D$6)+(U18*$D$7)+(V18*$D$8) -> -149500000
C13: Portfolio total | D13: =TSIR!J1080 -> 4.03699e+08
N14: Assue FV 100
B15: Q2 | L15: T (year) | M15: bond 1 pos | N15: bond 2 pos. | O15: bond 3 pos. | P15: Portf. zcb | Q15: Yt | R15: DF(T) | S15: X_T (discounted cahs flow map) | T15: Bond 1 | U15: Bond 2 | V15: Bond 3 | W15: MD= T/(1 + yT ) | X15: σ(dyT ) | Y15: MD ×σ(dyT ) = V
L16: 1 | M16: =0 * 2000000 -> 0 | N16: =FI_Portfolio!D5 * FI_Portfolio!B5 -> -7500000 | O16: =FI_Portfolio!D6 * FI_Portfolio!B6 -> 8000000 | P16: =M16 + N16 + O16 -> 500000 | Q16: =TSIR!B1080 -> 3.95 | R16: =1/((1+Q16/100)^L16) -> 0.96200096 | S16: =R16*((T16*$D$6)+(U16*$D$7)+(V16*$D$8)) -> 1.9288119e+08 | T16: 100 | U16: 5 | V16: 2 | W16: =L16/(1+Q16/100) -> 0.96200096 | X16: =_xlfn.STDEV.S(TSIR!L831:L1080) -> 0.044750374 | Y16: =W16*X16/100 -> 0.00043049903
L17: 2 | N17: =FI_Portfolio!D5 * FI_Portfolio!B5 -> -7500000 | O17: =FI_Portfolio!D6 * FI_Portfolio!B6 -> 8000000 | P17: =M17 + N17 + O17 -> 500000 | Q17: =TSIR!C1080 -> 3.74 | R17: =1/((1+Q17/100)^L17) -> 0.92919639 | S17: =R17*((T17*$D$6)+(U17*$D$7)+(V17*$D$8)) -> 464598.19 | T17: 0 | U17: 5 | V17: 2 | W17: =L17/(1+Q17/100) -> 1.9278967 | X17: =_xlfn.STDEV.S(TSIR!M831:M1080) -> 0.059178106 | Y17: =W17*X17/100 -> 0.0011408927
L18: 3 | N18: =(FI_Portfolio!D5 * FI_Portfolio!B5) + 100 -> -7499900 | O18: =FI_Portfolio!D6 * FI_Portfolio!B6 -> 8000000 | P18: =M18 + N18 + O18 -> 500100 | Q18: =TSIR!D1080 -> 3.76 | R18: =1/((1+Q18/100)^L18) -> 0.89517946 | S18: =R18*((T18*$D$6)+(U18*$D$7)+(V18*$D$8)) -> -1.3382933e+08 | T18: 0 | U18: 105 | V18: 2 | W18: =L18/(1+Q18/100) -> 2.8912876 | X18: =_xlfn.STDEV.S(TSIR!N831:N1080) -> 0.060028052 | Y18: =W18*X18/100 -> 0.0017355836
L19: 4 | O19: =FI_Portfolio!D6 * FI_Portfolio!B6 -> 8000000 | P19: =M19 + N19 + O19 -> 8000000 | Q19: =TSIR!E1080 -> 3.7865 | R19: =1/((1+Q19/100)^L19) -> 0.86185962 | S19: =R19*((T19*$D$6)+(U19*$D$7)+(V19*$D$8)) -> 6894877 | T19: 0 | U19: 0 | V19: 2 | W19: =L19/(1+Q19/100) -> 3.8540658 | X19: =_xlfn.STDEV.S(TSIR!O831:O1080) -> 0.048602164 | Y19: =W19*X19/100 -> 0.0018731594
L20: 5 | O20: =(FI_Portfolio!D6 * FI_Portfolio!B6) + 100 -> 8000100 | P20: =M20 + N20 + O20 -> 8000100 | Q20: =TSIR!F1080 -> 3.88 | R20: =1/((1+Q20/100)^L20) -> 0.82668545 | S20: =R20*((T20*$D$6)+(U20*$D$7)+(V20*$D$8)) -> 3.3728766e+08 | T20: 0 | U20: 0 | V20: 102 | W20: =L20/(1+Q20/100) -> 4.8132461 | X20: =_xlfn.STDEV.S(TSIR!P831:P1080) -> 0.060628886 | Y20: =W20*X20/100 -> 0.0029182175
Q24: R: | R24: correlation matrix of all 5 yields | X24: Diag V | AD24: Σ= diag(V) ×R ×diag(V)
R25: Column 1 | S25: Column 2 | T25: Column 3 | U25: Column 4 | V25: Column 5 | X25: {=_xlfn.MAKEARRAY(5, 5, _xlfn.LAMBDA(_xlpm.i,_xlpm.j, IF(_xlpm.i=_xlpm.j, INDEX(Y16:Y20, _xlpm.i), 0)))} -> 0.00043049903 | Y25: 0 | Z25: 0 | AA25: 0 | AB25: 0 | AD25: {=MMULT(MMULT(_xlfn.ANCHORARRAY(X25),R26:V30),_xlfn.ANCHORARRAY(X25))} -> 1.8532941e-07 | AE25: 4.4592361e-07 | AF25: 6.4768291e-07 | AG25: 6.5917749e-07 | AH25: 1.0063868e-06
Q26: Column 1 | R26: 1 | S26: 0.90791142 | T26: 0.86685153 | U26: 0.8174392 | V26: 0.80107858 | X26: 0 | Y26: 0.0011408927 | Z26: 0 | AA26: 0 | AB26: 0 | AD26: 4.4592361e-07 | AE26: 1.3016362e-06 | AF26: 1.8757374e-06 | AG26: 1.9049825e-06 | AH26: 3.027945e-06
Q27: Column 2 | R27: 0.90791142 | S27: 1 | T27: 0.94728722 | U27: 0.89139759 | V27: 0.909464 | X27: 0 | Y27: 0 | Z27: 0.0017355836 | AA27: 0 | AB27: 0 | AD27: 6.4768291e-07 | AE27: 1.8757374e-06 | AF27: 3.0122505e-06 | AG27: 3.0307417e-06 | AH27: 4.8143147e-06
Q28: Column 3 | R28: 0.86685153 | S28: 0.94728722 | T28: 1 | U28: 0.93224196 | V28: 0.95054192 | X28: 0 | Y28: 0 | Z28: 0 | AA28: 0.0018731594 | AB28: 0 | AD28: 6.5917749e-07 | AE28: 1.9049825e-06 | AF28: 3.0307417e-06 | AG28: 3.508726e-06 | AH28: 5.262503e-06
Q29: Column 4 | R29: 0.8174392 | S29: 0.89139759 | T29: 0.93224196 | U29: 1 | V29: 0.96271997 | X29: 0 | Y29: 0 | Z29: 0 | AA29: 0 | AB29: 0.0029182175 | AD29: 1.0063868e-06 | AE29: 3.027945e-06 | AF29: 4.8143147e-06 | AG29: 5.262503e-06 | AH29: 8.5159932e-06
Q30: Column 5 | R30: 0.80107858 | S30: 0.909464 | T30: 0.95054192 | U30: 0.96271997 | V30: 1
Q32: alpha | R32: 2.33
P33: 2.2) | Q33: VaR(99%, 1) | R33: {=R32* SQRT(MMULT(MMULT(TRANSPOSE(S16:S20),_xlfn.ANCHORARRAY( AD25)), S16:S20))} -> 1969010.2
Q34: ES(99%, 1) | R34: {=2.665 * SQRT(MMULT(MMULT(TRANSPOSE(S16:S20),_xlfn.ANCHORARRAY( AD25)), S16:S20))} -> 2252108.3
P37: 2.3) | Q37: VaR(99%, 1) | R37: =TSIR!AE3 -> 2112647.4
Q38: ES(99%, 1) | R38: =TSIR!AG3 -> 2491936.9

Sheet Part3
A1: date | B1: Exch. USD/CHF(250d) | C1: % change | D1: simulation exch. USD/CHF | E1: Bond 1 | F1: Bond 2 | G1: Bond 3 | H1: Portfolio Value | I1: Losses | J1: sorted losses | K1: VaR Bonds CHF(99%,1) | L1: ES bonds(99%,1) | M1: corr(Op.P, B.P) | N1: TOTAL VaR P. | O1: TOTAL ES | P1: Total UVaR | Q1: Total ES without correlation
A2: 45406 | B2: 0.91140002 | C2: =B2/0.91188997-1 -> -0.00053729057 | D2: =$B$252*(1+C2) -> 0.82829473 | E2: =TSIR!X3*D2 -> 79.659043 | F2: =TSIR!Y3*D2 -> 85.638572 | G2: =TSIR!Z3*D2 -> 75.852431 | H2: =E2*FI_Portfolio!$B$4+FI_Portfolio!$B$5*F2+FI_Portfolio!$B$6*G2 -> 3.3426995e+08 | I2: =H2-TSIR!$AM$5*$B$252 -> -291561.84 | J2: {=_xlfn._xlws.SORT(I2:I251)} -> -14705734 | K2: =ABS(_xlfn.PERCENTILE.INC(J1:J251,0.01)) -> 6343062 | L2: =ABS(AVERAGEIF(J2:J25, "<"&-K2)) -> 9553961.1 | M2: =CORREL(I2:I251,'Part 1'!Q396:Q645) -> 0.12555558 | N2: =SQRT(K2^2+'Part 1'!S396^2+2*M2*K2*'Part 1'!S396) -> 17505724 | O2: =SQRT(L2^2 + 'Part 1'!T396^2 + 2 * M2 * L2 * 'Part 1'!T396) -> 22581897 | P2: =K2+'Part 1'!S396 -> 21882205 | Q2: =L2+'Part 1'!T396 -> 28850818
A3: 45407 | B3: 0.91443998 | C3: =B3/B2-1 -> 0.0033354795 | D3: =$B$252*(1+C3) -> 0.83150425 | E3: =TSIR!X4*D3 -> 79.96002 | F3: =TSIR!Y4*D3 -> 85.854259 | G3: =TSIR!Z4*D3 -> 75.970302 | H3: =E3*FI_Portfolio!$B$4+FI_Portfolio!$B$5*F3+FI_Portfolio!$B$6*G3 -> 3.3501986e+08 | I3: =H3-TSIR!$AM$5*$B$252 -> 458345.64 | J3: -7543704.2 | K3: 3) | N3: sum var of 2 portfolios | P3: sum var of 2 portfolios no correlation
A4: 45408 | B4: 0.91251999 | C4: =B4/B3-1 -> -0.0020996291 | D4: =$B$252*(1+C4) -> 0.82699995 | E4: =TSIR!X5*D4 -> 79.557475 | F4: =TSIR!Y5*D4 -> 85.575484 | G4: =TSIR!Z5*D4 -> 75.836176 | H4: =E4*FI_Portfolio!$B$4+FI_Portfolio!$B$5*F4+FI_Portfolio!$B$6*G4 -> 3.3409643e+08 | I4: =H4-TSIR!$AM$5*$B$252 -> -465084.3 | J4: -6412445.6 | K4: VaR bond weight | L4: VaR option weight
A5: 45411 | B5: 0.913688 | C5: =B5/B4-1 -> 0.0012799858 | D5: =$B$252*(1+C5) -> 0.82980078 | E5: =TSIR!X6*D5 -> 79.834595 | F5: =TSIR!Y6*D5 -> 85.932664 | G5: =TSIR!Z6*D5 -> 76.12932 | H5: =E5*FI_Portfolio!$B$4+FI_Portfolio!$B$5*F5+FI_Portfolio!$B$6*G5 -> 3.3528747e+08 | I5: =H5-TSIR!$AM$5*$B$252 -> 725961.55 | J5: -6270846.4 | K5: =K2/N2 -> 0.36234217 | L5: =1-K5 -> 0.63765783
A6: 45412 | B6: 0.91071999 | C6: =B6/B5-1 -> -0.0032483882 | D6: =$B$252*(1+C6) -> 0.82604793 | E6: =TSIR!X7*D6 -> 79.427686 | F6: =TSIR!Y7*D6 -> 85.290503 | G6: =TSIR!Z7*D6 -> 75.438605 | H6: =E6*FI_Portfolio!$B$4+FI_Portfolio!$B$5*F6+FI_Portfolio!$B$6*G6 -> 3.3267404e+08 | I6: =H6-TSIR!$AM$5*$B$252 -> -1887475.5 | J6: -4465916.3
A7: 45413 | B7: 0.91948998 | C7: =B7/B6-1 -> 0.0096297315 | D7: =$B$252*(1+C7) -> 0.83672054 | E7: =TSIR!X8*D7 -> 80.523582 | F7: =TSIR!Y8*D7 -> 86.748343 | G7: =TSIR!Z8*D7 -> 76.940465 | H7: =E7*FI_Portfolio!$B$4+FI_Portfolio!$B$5*F7+FI_Portfolio!$B$6*G7 -> 3.3868651e+08 | I7: =H7-TSIR!$AM$5*$B$252 -> 4124998.7 | J7: -4111971.8
A8: 45414 | B8: 0.91636002 | C8: =B8/B7-1 -> -0.0034040165 | D8: =$B$252*(1+C8) -> 0.82591896 | E8: =TSIR!X9*D8 -> 79.491719 | F8: =TSIR!Y9*D8 -> 85.629595 | G8: =TSIR!Z9*D8 -> 75.914601 | H8: =E8*FI_Portfolio!$B$4+FI_Portfolio!$B$5*F8+FI_Portfolio!$B$6*G8 -> 3.3419745e+08 | I8: =H8-TSIR!$AM$5*$B$252 -> -364063.32 | J8: -3348343.6
A9: 45415 | B9: 0.90977001 | C9: =B9/B8-1 -> -0.0071915062 | D9: =$B$252*(1+C9) -> 0.82278011 | E9: =TSIR!X10*D9 -> 79.181995 | F9: =TSIR!Y10*D9 -> 85.301569 | G9: =TSIR!Z10*D9 -> 75.693297 | H9: =E9*FI_Portfolio!$B$4+FI_Portfolio!$B$5*F9+FI_Portfolio!$B$6*G9 -> 3.3318482e+08 | I9: =H9-TSIR!$AM$5*$B$252 -> -1376686.8 | J9: -3286397
A10: 45418 | B10: 0.90594 | C10: =B10/B9-1 -> -0.0042098724 | D10: =$B$252*(1+C10) -> 0.82525111 | E10: =TSIR!X11*D10 -> 79.389236 | F10: =TSIR!Y11*D10 -> 85.348925 | G10: =TSIR!Z11*D10 -> 75.608475 | H10: =E10*FI_Portfolio!$B$4+FI_Portfolio!$B$5*F10+FI_Portfolio!$B$6*G10 -> 3.3318898e+08 | I10: =H10-TSIR!$AM$5*$B$252 -> -1372528.4 | J10: -3185424.4
A11: 45419 | B11: 0.90670002 | C11: =B11/B10-1 -> 0.00083892844 | D11: =$B$252*(1+C11) -> 0.82943525 | E11: =TSIR!X12*D11 -> 79.784076 | F11: =TSIR!Y12*D11 -> 85.894786 | G11: =TSIR!Z12*D11 -> 75.993897 | H11: =E11*FI_Portfolio!$B$4+FI_Portfolio!$B$5*F11+FI_Portfolio!$B$6*G11 -> 3.3470156e+08 | I11: =H11-TSIR!$AM$5*$B$252 -> 140050.06 | J11: -3123365.6
A12: 45420 | B12: 0.90847999 | C12: =B12/B11-1 -> 0.0019631339 | D12: =$B$252*(1+C12) -> 0.83036693 | E12: =TSIR!X13*D12 -> 79.881378 | F12: =TSIR!Y13*D12 -> 85.832171 | G12: =TSIR!Z13*D12 -> 76.006828 | H12: =E12*FI_Portfolio!$B$4+FI_Portfolio!$B$5*F12+FI_Portfolio!$B$6*G12 -> 3.3504181e+08 | I12: =H12-TSIR!$AM$5*$B$252 -> 480298.66 | J12: -3011268
A13: 45421 | B13: 0.90798998 | C13: =B13/B12-1 -> -0.00053937323 | D13: =$B$252*(1+C13) -> 0.828293 | E13: =TSIR!X14*D13 -> 79.689532 | F13: =TSIR!Y14*D13 -> 85.757692 | G13: =TSIR!Z14*D13 -> 75.991665 | H13: =E13*FI_Portfolio!$B$4+FI_Portfolio!$B$5*F13+FI_Portfolio!$B$6*G13 -> 3.3470919e+08 | I13: =H13-TSIR!$AM$5*$B$252 -> 147676.75 | J13: -3004402.6
A14: 45422 | B14: 0.90584999 | C14: =B14/B13-1 -> -0.0023568383 | D14: =$B$252*(1+C14) -> 0.82678679 | E14: =TSIR!X15*D14 -> 79.49873 | F14: =TSIR!Y15*D14 -> 85.411626 | G14: =TSIR!Z15*D14 -> 75.574594 | H14: =E14*FI_Portfolio!$B$4+FI_Portfolio!$B$5*F14+FI_Portfolio!$B$6*G14 -> 3.331784e+08 | I14: =H14-TSIR!$AM$5*$B$252 -> -1383114.2 | J14: -2965536.9
A15: 45425 | B15: 0.90644997 | C15: =B15/B14-1 -> 0.00066233964 | D15: =$B$252*(1+C15) -> 0.82928891 | E15: =TSIR!X16*D15 -> 79.785348 | F15: =TSIR!Y16*D15 -> 85.769134 | G15: =TSIR!Z16*D15 -> 76.045958 | H15: =E15*FI_Portfolio!$B$4+FI_Portfolio!$B$5*F15+FI_Portfolio!$B$6*G15 -> 3.3510083e+08 | I15: =H15-TSIR!$AM$5*$B$252 -> 539313.65 | J15: -2945494.7
A16: 45426 | B16: 0.90789998 | C16: =B16/B15-1 -> 0.0015996494 | D16: =$B$252*(1+C16) -> 0.83006569 | E16: =TSIR!X17*D16 -> 79.8524 | F16: =TSIR!Y17*D16 -> 85.963433 | G16: =TSIR!Z17*D16 -> 76.18876 | H16: =E16*FI_Portfolio!$B$4+FI_Portfolio!$B$5*F16+FI_Portfolio!$B$6*G16 -> 3.3551469e+08 | I16: =H16-TSIR!$AM$5*$B$252 -> 953178.51 | J16: -2825177.9
A17: 45427 | B17: 0.90670002 | C17: =B17/B16-1 -> -0.0013216882 | D17: =$B$252*(1+C17) -> 0.82764466 | E17: =TSIR!X18*D17 -> 79.665479 | F17: =TSIR!Y18*D17 -> 85.875878 | G17: =TSIR!Z18*D17 -> 76.210815 | H17: =E17*FI_Portfolio!$B$4+FI_Portfolio!$B$5*F17+FI_Portfolio!$B$6*G17 -> 3.353604e+08 | I17: =H17-TSIR!$AM$5*$B$252 -> 798891.78 | J17: -2771193.4
... A247: 45764 | B247: 0.81375003 | C247: =B247/B246-1 -> -0.0085529398 | D247: =$B$252*(1+C247) -> 0.82165184 | E247: =TSIR!X248*D247 -> 79.02018 | F247: =TSIR!Y248*D247 -> 84.884121 | G247: =TSIR!Z248*D247 -> 75.140234 | H247: =E247*FI_Portfolio!$B$4+FI_Portfolio!$B$5*F247+FI_Portfolio!$B$6*G247 -> 3.3127511e+08 | I247: =H247-TSIR!$AM$5*$B$252 -> -3286397 | J247: 3329352.4
A248: 45768 | B248: =AVERAGE(B249,B247) -> 0.81140003 | C248: =B248/B247-1 -> -0.0028878678 | D248: =$B$252*(1+C248) -> 0.82634671 | E248: =TSIR!X249*D248 -> 79.525234 | F248: =TSIR!Y249*D248 -> 85.603795 | G248: =TSIR!Z249*D248 -> 75.645646 | H248: =E248*FI_Portfolio!$B$4+FI_Portfolio!$B$5*F248+FI_Portfolio!$B$6*G248 -> 3.3322736e+08 | I248: =H248-TSIR!$AM$5*$B$252 -> -1334150.5 | J248: 4041656.1
A249: 45769 | B249: 0.80905002 | C249: =B249/B248-1 -> -0.0028962318 | D249: =$B$252*(1+C249) -> 0.82633978 | E249: =TSIR!X250*D249 -> 79.471031 | F249: =TSIR!Y250*D249 -> 85.370647 | G249: =TSIR!Z250*D249 -> 75.670682 | H249: =E249*FI_Portfolio!$B$4+FI_Portfolio!$B$5*F249+FI_Portfolio!$B$6*G249 -> 3.3356882e+08 | I249: =H249-TSIR!$AM$5*$B$252 -> -992693.39 | J249: 4124998.7
A250: 45770 | B250: 0.82607001 | C250: =B250/B249-1 -> 0.021037002 | D250: =$B$252*(1+C250) -> 0.84617421 | E250: =TSIR!X251*D250 -> 81.378554 | F250: =TSIR!Y251*D250 -> 87.416748 | G250: =TSIR!Z251*D250 -> 77.450928 | H250: =E250*FI_Portfolio!$B$4+FI_Portfolio!$B$5*F250+FI_Portfolio!$B$6*G250 -> 3.414357e+08 | I250: =H250-TSIR!$AM$5*$B$252 -> 6874186 | J250: 6356194.9
A251: 45771 | B251: 0.82980001 | C251: =B251/B250-1 -> 0.0045153547 | D251: =$B$252*(1+C251) -> 0.83248206 | E251: =TSIR!X252*D251 -> 80.115682 | F251: =TSIR!Y252*D251 -> 86.283234 | G251: =TSIR!Z252*D251 -> 76.583486 | H251: =E251*FI_Portfolio!$B$4+FI_Portfolio!$B$5*F251+FI_Portfolio!$B$6*G251 -> 3.3714046e+08 | I251: =H251-TSIR!$AM$5*$B$252 -> 2578944.8 | J251: 6874186
A252: 45772 | B252: 0.82874 | C252: =B252/B251-1 -> -0.001277428 | D252: =$B$252*(1+C252) -> 0.82768134

Sheet Sheet
B1: Column 1
A2: Column 1 | B2: 1
